Workbook
Name Above400M: #REF!
Name Above400M: #REF!
Name Above400M: #REF!
Name Baseline: #REF!
Name Baseline: #REF!
Name Below400M: #REF!
Name Contract: #REF!
Name Contract: #REF!
Name Distributor: #REF!
Name Distributor: #REF!
Name Entity: #REF!
Name Entity: #REF!
Name Final: #REF!
Name Final: #REF!
Name Foreign: #REF!
Name Goods: 'Appendix B'!$A$25:$B$25
Name Level: #REF!
Name Level: #REF!
Name LevelSelection: #REF!
Name LevelSelection: #REF!
Name ListTypes: #REF!
Name ListTypes: #REF!
Name NoContract: #REF!
Name NoContract: #REF!
Name Other: #REF!
Name Other: #REF!
Name Periodic: #REF!
Name Periodic: #REF!
Name Producer: #REF!
Name Producer: #REF!
Name Product: #REF!
Name Product: #REF!
Name Provider: #REF!
Name Provider: #REF!
Name Purpose: #REF!
Name Purpose: #REF!
Name PurposeSelection: #REF!
Name PurposeSelection: #REF!
Name ScenarioLabelIDs: #REF!
Name ScenarioLabelIDs: #REF!
Name ScenarioLabels: #REF!
Name ScenarioLabels: #REF!
Name Services: 'Appendix B'!$A$5:$B$5
Name Supplementary: #REF!
Name Supplementary: #REF!
Name Supplier: #REF!
Name Supplier: #REF!
Name SupplierTypes: #REF!
Name SupplierTypes: #REF!
Name Target: #REF!
Name Target: #REF!
Name Value: #REF!
Name Value: #REF!
Name Value: #REF!
Name ValueSelection: #REF!
Name ValueSelection: #REF!

Sheet Overview
F2: Local Content Score Template Local Content and Government Procurement Authority Template (N.1)
L3: Template Code | M3: OM-LRG-02
L4: Version Number | M4: V.2
B9: Overview | O9: Format
B10: The Local Content Template is provided by the Local Content and Government Procurement Authority to allow the entity to measure its contribution to Local Content. This Template provides a unified tool for reporting Local Content Score.
P11: ABC | Q11: Heading of the table
P12: ABC | Q12: Heading of the column or row
P13: ABC | Q13: Formula or pre-filled data
P14: ABC | Q14: Data to be filled by the Entity
B18: Contents | F18: Description
B19: Section 1. General Information | F19: General information about the entity and the types of products and services it provides
B20: Section 2. Evaluation | F20: Calculation and evaluation of the Local Content score for the entity
B21: Section 3. Labor | F21: The Entity's relevant expenses on labor compensation for the reported financial year
B22: Section 4. Goods & Services | F22: The Entity's relevant Goods and Services expenses for the reported financial year
B23: Section 4.1. Extra Disclosure | F23: The Entity's relevant Extra Disclosed Goods expenses for the reported financial year
B24: Section 5. CAPEX | F24: The Entity's Capital expenditures for the reported financial year
B25: Section 6. Capacity Building | F25: The Entity's relevant expenses on KSA capacity building for the reported financial year
B26: Section 7. Depreciation and Amortization | F26: The Entity's depreciation and amortization for the reported financial year
B27: Appendix A. | F27: The Entity’s expenses as per its audited financial statements for the reported financial year
B28: Appendix B. | F28: Local content scores for Goods and Services sectors
B30: *This document was originally prepared in Arabic, and the Arabic version should prevail

Sheet Section 1. General Information
B1: Section 1: General Information
B2: 1.1 Tender Information (To be used only if the purpose of issuing the local content certificate is to submit a periodic or final report related to a specific project)
B3: Project Owner
B4: Tender Name
B5: Contract Start Date (DD/MM/YYYY)
B6: Contract End Date (DD/MM/YYYY)
B8: 1.2 Entity Information
B9: Full Name
B10: Main Address
B11: End of Financial Year (MM/DD/YYYY)1
B12: KSA Unified National Number2
B14: 1.3 Contact Person
... B24: Disclosure general information about the subsidiaries consolidated in this Template
B25: Full name | C25: KSA Unified National Number | D25: Description of business activities
A26: 1
A27: 2
A28: 3
A29: 4
A30: 5
A31: 6
A32: 7
A33: 8
A34: 9
A35: 10
A36: 11
A37: 12
... A45: 20
B47: 1. The end date of the reported financial year.
B48: 2. The entity's Unified National Number, if it is not available, enter the License Number, or please enter “Not applicable” to indicate that it does not have a unified national number or a license number in the Kingdom of Saudi Arabia.

Sheet Section 2. Evaluation
B1: Section 2: Evaluation of Local Content
B2: Contract Information
B3: Entity Name | C3: =IF('Section 1. General Information'!$C$9:$D$9="","",'Section 1. General Information'!$C$9:$D$9)
B4: Tender Name | C4: =IF('Section 1. General Information'!$C$4:$D$4="","",'Section 1. General Information'!$C$4:$D$4)
B5: Contract Start Date (DD/MM/YYYY) | C5: =IF('Section 1. General Information'!$C$5:$D$5="","",'Section 1. General Information'!$C$5:$D$5)
B6: Contract End Date (DD/MM/YYYY) | C6: =IF('Section 1. General Information'!$C$6:$D$6="","",'Section 1. General Information'!$C$6:$D$6)
B8: 2.1 Local Content Score1
B9: Evaluation Criteria | C9: Contribution to Local Content (SAR)
B10: Local Content from depreciation and amortization | C10: ='Section 7. Depreciation & Amor.'!C10 -> 0
B11: Local Content from labor | C11: ='Section 3. Labor'!E12 -> 0
B12: Local Content from Goods and Services | C12: ='Section 4. Goods and Services'!F10 -> 0
B13: Local Content from Saudi training | C13: ='Section 6. Capacity Building'!C9 -> 0
B14: Local Content from Supplier development | C14: ='Section 6. Capacity Building'!C12 -> 0
B15: Local Content from research and development | C15: ='Section 6. Capacity Building'!C15 -> 0
B16: Total Local Content Contribution | C16: =SUM(C10:E15) -> 0
B17: Total Relevant Cost of Operations in the Kingdom of Saudi Arabia2 | C17: ='Section 3. Labor'!E10+'Section 4. Goods and Services'!F9+'Section 6. Capacity Building'!C9+'Section 6. Capacity Building'!C12+'Section 6. Capacity Building'!C15+'Section 7. Depreciation & Amor.'!C9 -> 0
B18: Local Content Score (%) | C18: =IFERROR(IF(((C16/C17)+'Section 6. Capacity Building'!C17)>1,1,((C16/C17)+'Section 6. Capacity Building'!C17)),0) -> 0
B19: Export Revenue Score (%)3 | C19: ='Appendix A'!F47 -> 0
B21: 1. The local content score shows the actual value contributed by the entity during the reported financial year.
B22: 2. The total cost during the reported financial year for operational activities including employee compensation, goods and services, capacity building, and depreciation and amortization of assets.
B23: 3. The maximum score of export revenue is 10%, and it is not calculated in the local content score. LCGPA does not grant any benefits or incentives for this score.

Sheet Section 3. Labor
B1: Section 3: Labor
B2: Contract Information
B3: Entity Name | C3: =IF('Section 1. General Information'!$C$9:$D$9="","",'Section 1. General Information'!$C$9:$D$9)
B4: Tender Name | C4: =IF('Section 1. General Information'!$C$4:$D$4="","",'Section 1. General Information'!$C$4:$D$4)
B5: Contract Start Date (DD/MM/YYYY) | C5: =IF('Section 1. General Information'!$C$5:$D$5="","",'Section 1. General Information'!$C$5:$D$5)
B6: Contract End Date (DD/MM/YYYY) | C6: =IF('Section 1. General Information'!$C$6:$D$6="","",'Section 1. General Information'!$C$6:$D$6)
B8: 3.1 Labor Compensations for the Reported Financial Year1
C9: Compensation of Saudi Employees (SAR)3 | D9: Compensation of foreign Employees (SAR) | E9: Total Compensation (SAR)
B10: Total compensation (SAR)2 | C10: 0 | D10: 0 | E10: =SUM(C10:D10) -> 0
B11: Contribution to Local Content (%) | C11: 1 | D11: 0.534 | E11: =IFERROR(E12/E10,0) -> 0
B12: Contribution to Local Content (SAR) | C12: =C10*C11 -> 0 | D12: =D10*D11 -> 0 | E12: =SUM(C12:D12) -> 0
B14: 3.2 Average count of the employees for the Reported Financial Year
C15: Saudi Employees3 | D15: Foreign Employees | E15: Total
B16: Average count of Male Employees | C16: 0 | D16: 0 | E16: =SUM(C16:D16) -> 0
B17: Average count of Femal Employees | C17: 0 | D17: 0 | E17: =SUM(C17:D17) -> 0
B18: Average Employees Count | C18: =SUM(C16:C17) -> 0 | D18: =SUM(D16:D17) -> 0 | E18: =SUM(E16:E17) -> 0
B20: 1. Compensation of Saudi and foreign employees of the entity in the Kingdom of Saudi Arabia during the reported financial year, excluding the training expenses of Saudis included in Section 5 “Capacity Building”.
B21: 2. Employees compensations includes salaries, wages, bonuses and benefits (e.g.: commissions, overtime, transportation allowances, housing allowances, vacations, other allowances, end-of-service benefits provision, and General Organization for Social Insurance (“GOSI”) contributions).
B22: 3. A Saudi employee is any person who holds Saudi nationality or who is legally treated as a Saudi.

Sheet Section 4. Goods and Services
B1: Section 4: Goods and Services
B2: Contract information
B3: Entity Name | C3: =IF('Section 1. General Information'!$C$9:$D$9="","",'Section 1. General Information'!$C$9:$D$9)
B4: Tender Name | C4: =IF('Section 1. General Information'!$C$4:$D$4="","",'Section 1. General Information'!$C$4:$D$4)
B5: Contract Start Date (DD/MM/YYYY) | C5: =IF('Section 1. General Information'!$C$5:$D$5="","",'Section 1. General Information'!$C$5:$D$5)
B6: Contract End Date (DD/MM/YYYY) | C6: =IF('Section 1. General Information'!$C$6:$D$6="","",'Section 1. General Information'!$C$6:$D$6)
B8: 4.1 Expenses for the Reported Financial Year
B9: Total Expense of Goods and Services (SAR)1 | F9: 0
B10: Contribution to Local Content from Goods and Services (SAR) | F10: =O97 -> 0
B12: 4.2 Expenses on Goods and Services for the Reported Financial Year
B13: Full name2,3 | E13: Unified National Number or KSA Commercial registration number4 | F13: Brief description of the goods or services provided | G13: Goods/Services | H13: Local/Foreign | I13: Factory Manufactored the supplied good, and Unified National Number -if Available-5 | J13: Sector of the goods or services procured from the supplier | K13: Audited Score (%), If applicable6 | L13: Sector Score (%) | M13: Selected Score (%) | N13: Total Expenses (SAR)7 | O13: Local Content Contribution (SAR)
A14: 1 | L14: =IFERROR(INDEX('Appendix B'!$C$5:$C$42,MATCH('Section 4. Goods and Services'!J14,'Appendix B'!$B$5:$B$42,0)),0) -> 0 | M14: =IF(K14<=0,L14,K14) -> 0 | N14: 0 | O14: =N14*M14 -> 0 | P14: =IF(O14>1%*'Section 2. Evaluation'!$C$17,"To be confirmed","")
A15: =A14+1 -> 2 | L15: =IFERROR(INDEX('Appendix B'!$C$5:$C$42,MATCH('Section 4. Goods and Services'!J15,'Appendix B'!$B$5:$B$42,0)),0) -> 0 | M15: =IF(K15<=0,L15,K15) -> 0 | N15: 0 | O15: =N15*M15 -> 0 | P15: =IF(O15>1%*'Section 2. Evaluation'!$C$17,"To be confirmed","")
A16: =A15+1 -> 3 | L16: =IFERROR(INDEX('Appendix B'!$C$5:$C$42,MATCH('Section 4. Goods and Services'!J16,'Appendix B'!$B$5:$B$42,0)),0) -> 0 | M16: =IF(K16<=0,L16,K16) -> 0 | N16: 0 | O16: =N16*M16 -> 0 | P16: =IF(O16>1%*'Section 2. Evaluation'!$C$17,"To be confirmed","")
A17: =A16+1 -> 4 | L17: =IFERROR(INDEX('Appendix B'!$C$5:$C$42,MATCH('Section 4. Goods and Services'!J17,'Appendix B'!$B$5:$B$42,0)),0) -> 0 | M17: =IF(K17<=0,L17,K17) -> 0 | N17: 0 | O17: =N17*M17 -> 0 | P17: =IF(O17>1%*'Section 2. Evaluation'!$C$17,"To be confirmed","")
A18: =A17+1 -> 5 | L18: =IFERROR(INDEX('Appendix B'!$C$5:$C$42,MATCH('Section 4. Goods and Services'!J18,'Appendix B'!$B$5:$B$42,0)),0) -> 0 | M18: =IF(K18<=0,L18,K18) -> 0 | N18: 0 | O18: =N18*M18 -> 0 | P18: =IF(O18>1%*'Section 2. Evaluation'!$C$17,"To be confirmed","")
A19: =A18+1 -> 6 | L19: =IFERROR(INDEX('Appendix B'!$C$5:$C$42,MATCH('Section 4. Goods and Services'!J19,'Appendix B'!$B$5:$B$42,0)),0) -> 0 | M19: =IF(K19<=0,L19,K19) -> 0 | N19: 0 | O19: =N19*M19 -> 0 | P19: =IF(O19>1%*'Section 2. Evaluation'!$C$17,"To be confirmed","")
A20: =A19+1 -> 7 | L20: =IFERROR(INDEX('Appendix B'!$C$5:$C$42,MATCH('Section 4. Goods and Services'!J20,'Appendix B'!$B$5:$B$42,0)),0) -> 0 | M20: =IF(K20<=0,L20,K20) -> 0 | N20: 0 | O20: =N20*M20 -> 0 | P20: =IF(O20>1%*'Section 2. Evaluation'!$C$17,"To be confirmed","")
A21: =A20+1 -> 8 | L21: =IFERROR(INDEX('Appendix B'!$C$5:$C$42,MATCH('Section 4. Goods and Services'!J21,'Appendix B'!$B$5:$B$42,0)),0) -> 0 | M21: =IF(K21<=0,L21,K21) -> 0 | N21: 0 | O21: =N21*M21 -> 0 | P21: =IF(O21>1%*'Section 2. Evaluation'!$C$17,"To be confirmed","")
A22: =A21+1 -> 9 | L22: =IFERROR(INDEX('Appendix B'!$C$5:$C$42,MATCH('Section 4. Goods and Services'!J22,'Appendix B'!$B$5:$B$42,0)),0) -> 0 | M22: =IF(K22<=0,L22,K22) -> 0 | N22: 0 | O22: =N22*M22 -> 0 | P22: =IF(O22>1%*'Section 2. Evaluation'!$C$17,"To be confirmed","")
A23: =A22+1 -> 10 | L23: =IFERROR(INDEX('Appendix B'!$C$5:$C$42,MATCH('Section 4. Goods and Services'!J23,'Appendix B'!$B$5:$B$42,0)),0) -> 0 | M23: =IF(K23<=0,L23,K23) -> 0 | N23: 0 | O23: =N23*M23 -> 0 | P23: =IF(O23>1%*'Section 2. Evaluation'!$C$17,"To be confirmed","")
A24: =A23+1 -> 11 | L24: =IFERROR(INDEX('Appendix B'!$C$5:$C$42,MATCH('Section 4. Goods and Services'!J24,'Appendix B'!$B$5:$B$42,0)),0) -> 0 | M24: =IF(K24<=0,L24,K24) -> 0 | N24: 0 | O24: =N24*M24 -> 0 | P24: =IF(O24>1%*'Section 2. Evaluation'!$C$17,"To be confirmed","")
A25: =A24+1 -> 12 | L25: =IFERROR(INDEX('Appendix B'!$C$5:$C$42,MATCH('Section 4. Goods and Services'!J25,'Appendix B'!$B$5:$B$42,0)),0) -> 0 | M25: =IF(K25<=0,L25,K25) -> 0 | N25: 0 | O25: =N25*M25 -> 0 | P25: =IF(O25>1%*'Section 2. Evaluation'!$C$17,"To be confirmed","")
A26: =A25+1 -> 13 | L26: =IFERROR(INDEX('Appendix B'!$C$5:$C$42,MATCH('Section 4. Goods and Services'!J26,'Appendix B'!$B$5:$B$42,0)),0) -> 0 | M26: =IF(K26<=0,L26,K26) -> 0 | N26: 0 | O26: =N26*M26 -> 0 | P26: =IF(O26>1%*'Section 2. Evaluation'!$C$17,"To be confirmed","")
... A93: =A92+1 -> 80 | L93: =IFERROR(INDEX('Appendix B'!$C$5:$C$42,MATCH('Section 4. Goods and Services'!J93,'Appendix B'!$B$5:$B$42,0)),0) -> 0 | M93: =IF(K93<=0,L93,K93) -> 0 | N93: 0 | O93: =N93*M93 -> 0 | P93: =IF(O93>1%*'Section 2. Evaluation'!$C$17,"To be confirmed","")
B94: Other Disallowable Costs (unallocated cost) | M94: 0 | N94: 0 | O94: =N94*M94 -> 0
B95: Inventory Movement (+/-)8 | M95: =IFERROR(SUMPRODUCT($N$14:$N$94,$M$14:$M$94)/SUM($N$14:$N$94),0) -> 0 | N95: 0 | O95: =M95*N95 -> 0
B96: Remaining expenses9 | M96: =IFERROR(SUMPRODUCT($N$14:$N$94,$M$14:$M$94)/SUM($N$14:$N$94),0) -> 0 | N96: =F9-SUM(N14:N95) -> 0 | O96: =N96*M96 -> 0
B97: Total Expense | N97: =SUM(N14:N96) -> 0 | O97: =SUM(O14:O96) -> 0
B98: Has the required percentage or number of suppliers been covered? | N98: =IFERROR(IF(F9=0,"",IF(OR(COUNTIFS($N$14:$N$93,">"&0)>=10,N96=0),IF(OR((SUM($N$14:$N$53,$N$94:$N$95)/F9)>=70%,COUNTIFS($N$14:$N$53,">"&0)>=40),IF(OR(N96<500000000,COUNTIFS($N$14:$N$93,">"&0)=80),"Yes","No"),"No"),"No")),"")
B99: Has the required percentage or supplied goods been covered?10 | N99: =IFERROR(IF(F9=0,"",IF((SUMIFS($N$14:$N$93,$G$14:$G$93,"Goods")/$F$9)<50%,"You need to list 40 suppliers of goods in 4.1 Extra Disclosure","Yes")),"No")
B101: 1. Includes the operating expenses and overhead costs of the entity on goods and services for the reported financial year.
B102: 2. List at least 10 suppliers or the remaining expenses is zero, whichever comes first.
B103: 3. List at least 70% or top 40 suppliers of the total expenses on Goods and Services in descending order by cost. The entity should contact LCGPA, in order to list more than 80 suppliers.
B104: 4. Supplier's Unified National Number/Commercial Registration Number in the Kingdom of Saudi Arabia, and if it is not available, please enter the license number or “not applicable” to indicate that the supplier does not have a Unified National Number/Commercial Registration Number or license number in the Kingdom of Saudi Arabia.
B105: 5. The Factory that manufactured the supplied good and the Unified National Number/Commercial Registeration number of the factory -if available- in case the supplier is not the manufacturer of the goods.
B106: 6. Enter the supplier's latest audited score (The Entity Level) or use the sector score of the consumed goods or services.
B107: 7. Total expenses refer to the value of total purchases, consumed materials or provided services from suppliers -individually- by the entity in the reported financial year, as per the guidelines and related instructions.
B108: 8. Inventory movement should only apply if consumption data is not available and purchasing data is being utilized, as per the Guidelines and related instructions.
B109: 9. If the remaining expenses are equal to or more than SAR 500 million, list the top 80 suppliers in descending order by cost or until the remaining expenses is less than SAR 500 million, whichever comes first.
...

Sheet Section 4.1 Extra Disclosure
B2: Section 4.1: Extra Disclosure of Goods (the purpose of this section is to disclose extra suppliers of goods during the reported financial year, and it does not affect the calculation of the local content score
B5: 4.1.1 Expenses for the Reported Financial Year
B6: Remaining expenses | F6: ='Section 4. Goods and Services'!$N$96 -> 0
B7: percentage of supplied goods in the goods and services section and Extra Disclosure section (%) | F7: =IFERROR((SUM($M$11:$M$50)+SUMIFS('Section 4. Goods and Services'!$N$14:$N$93,'Section 4. Goods and Services'!$G$14:$G$93,"Goods"))/'Section 4. Goods and Services'!$F$9,0) -> 0
B9: 4.1.2 Expenses on Goods for the Reported Financial Year
B10: Full name1 | E10: Unified National Number or KSA Commercial registration number2 | F10: Brief description of the goods provided | G10: Local/Foreign | H10: Factory Manufactored the supplied good, and Unified National Number -if Available-3 | I10: Sector of the goods or services procured from the supplier | J10: Audited Score (%), If applicable4 | K10: Sector Score (%) | L10: Selected Score (%) | M10: Total Expenses (SAR)5
A11: 1 | K11: =IFERROR(INDEX('Appendix B'!$C$5:$C$42,MATCH('Section 4.1 Extra Disclosure'!I11,'Appendix B'!$B$5:$B$42,0)),0) -> 0 | L11: =IF(J11<=0,K11,J11) -> 0 | M11: 0
A12: =A11+1 -> 2 | K12: =IFERROR(INDEX('Appendix B'!$C$5:$C$42,MATCH('Section 4.1 Extra Disclosure'!I12,'Appendix B'!$B$5:$B$42,0)),0) -> 0 | L12: =IF(J12<=0,K12,J12) -> 0 | M12: 0
A13: =A12+1 -> 3 | K13: =IFERROR(INDEX('Appendix B'!$C$5:$C$42,MATCH('Section 4.1 Extra Disclosure'!I13,'Appendix B'!$B$5:$B$42,0)),0) -> 0 | L13: =IF(J13<=0,K13,J13) -> 0 | M13: 0
A14: =A13+1 -> 4 | K14: =IFERROR(INDEX('Appendix B'!$C$5:$C$42,MATCH('Section 4.1 Extra Disclosure'!I14,'Appendix B'!$B$5:$B$42,0)),0) -> 0 | L14: =IF(J14<=0,K14,J14) -> 0 | M14: 0
A15: =A14+1 -> 5 | K15: =IFERROR(INDEX('Appendix B'!$C$5:$C$42,MATCH('Section 4.1 Extra Disclosure'!I15,'Appendix B'!$B$5:$B$42,0)),0) -> 0 | L15: =IF(J15<=0,K15,J15) -> 0 | M15: 0
A16: =A15+1 -> 6 | K16: =IFERROR(INDEX('Appendix B'!$C$5:$C$42,MATCH('Section 4.1 Extra Disclosure'!I16,'Appendix B'!$B$5:$B$42,0)),0) -> 0 | L16: =IF(J16<=0,K16,J16) -> 0 | M16: 0
A17: =A16+1 -> 7 | K17: =IFERROR(INDEX('Appendix B'!$C$5:$C$42,MATCH('Section 4.1 Extra Disclosure'!I17,'Appendix B'!$B$5:$B$42,0)),0) -> 0 | L17: =IF(J17<=0,K17,J17) -> 0 | M17: 0
A18: =A17+1 -> 8 | K18: =IFERROR(INDEX('Appendix B'!$C$5:$C$42,MATCH('Section 4.1 Extra Disclosure'!I18,'Appendix B'!$B$5:$B$42,0)),0) -> 0 | L18: =IF(J18<=0,K18,J18) -> 0 | M18: 0
A19: =A18+1 -> 9 | K19: =IFERROR(INDEX('Appendix B'!$C$5:$C$42,MATCH('Section 4.1 Extra Disclosure'!I19,'Appendix B'!$B$5:$B$42,0)),0) -> 0 | L19: =IF(J19<=0,K19,J19) -> 0 | M19: 0
A20: =A19+1 -> 10 | K20: =IFERROR(INDEX('Appendix B'!$C$5:$C$42,MATCH('Section 4.1 Extra Disclosure'!I20,'Appendix B'!$B$5:$B$42,0)),0) -> 0 | L20: =IF(J20<=0,K20,J20) -> 0 | M20: 0
A21: =A20+1 -> 11 | K21: =IFERROR(INDEX('Appendix B'!$C$5:$C$42,MATCH('Section 4.1 Extra Disclosure'!I21,'Appendix B'!$B$5:$B$42,0)),0) -> 0 | L21: =IF(J21<=0,K21,J21) -> 0 | M21: 0
A22: =A21+1 -> 12 | K22: =IFERROR(INDEX('Appendix B'!$C$5:$C$42,MATCH('Section 4.1 Extra Disclosure'!I22,'Appendix B'!$B$5:$B$42,0)),0) -> 0 | L22: =IF(J22<=0,K22,J22) -> 0 | M22: 0
A23: =A22+1 -> 13 | K23: =IFERROR(INDEX('Appendix B'!$C$5:$C$42,MATCH('Section 4.1 Extra Disclosure'!I23,'Appendix B'!$B$5:$B$42,0)),0) -> 0 | L23: =IF(J23<=0,K23,J23) -> 0 | M23: 0
... A50: =A49+1 -> 40 | K50: =IFERROR(INDEX('Appendix B'!$C$5:$C$42,MATCH('Section 4.1 Extra Disclosure'!I50,'Appendix B'!$B$5:$B$42,0)),0) -> 0 | L50: =IF(J50<=0,K50,J50) -> 0 | M50: 0
B51: Remaining expenses after the extra disclosure | M51: =F6-SUM(M11:M50) -> 0
B52: Total Expense | M52: =SUM('Section 4. Goods and Services'!$N$14:$N$95)+SUM($M$11:$M$51) -> 0
B54: 1. If the disclosed goods in Section 4.Goods and Services are less than 50% of the total expenses of goods and services, list 40 suppliers in descending order by cost, or until the remaining expenses is zero, whichever comes first.
B55: 2. Supplier's Unified National Number/Commercial Registration Number in the Kingdom of Saudi Arabia, and if it is not available, please enter the license number or “not applicable” to indicate that the supplier does not have a Unified National Number/Commercial Registration Number or license number in the Kingdom of Saudi Arabia.
B56: 3. The Factory that manufactured the supplied good and the Unified National Number/Commercial Registeration number of the factory -if available- in case the factory is not the supplier of the goods.
B57: 4. Enter the supplier's latest audited score or use the sector score of the consumed goods or services.
B58: 5. Total expenses refer to the value of total purchases, consumed materials or provided services from suppliers -individually- by the entity in the reported financial year, as per the Guidelines and related instructions.

Sheet Section 5. CAPEX
B2: 5. Capital expenditures (the purpose of this section is to disclose the additions on the capital expenditures during the reported financial year, and it does not affect the calculation of the local content score)
B4: 5.1 Capital Expenditures for the Reported Financial Year
B5: Total Capital Expenditures 1,2 | C5: 0 | D5: =IF(C5>=100000000,"Must disclose the additions of capital expenditures in table 5.2","")
B6: Contribution to Local Content from Capital Expenditures | C6: =N94 -> 0
B7: Local Content Score from Capital Expenditures (%) | C7: =IFERROR(C6/(C5-M92),0) -> 0
B9: 5.2 Capital Expenditures for the Reported Financial Year
B10: Assets Type 3 | C10: Brief Description for Assets/CAPEX | D10: Supplier Name | E10: KSA Commercial registration number4 | F10: Goods/Services | G10: Local/Foreign | H10: Factory Manufactored the supplied good, and Unified National Number -if Available-5 | I10: Sector of the goods or services procured from the supplier | J10: Audited Score (%), If applicable6 | K10: Sector Score (%) | L10: Selected Score (%) | M10: Total Expenditures (SAR)7 | N10: Local Content Contribution (SAR)
A11: 1 | K11: =IFERROR(INDEX('Appendix B'!$C$5:$C$42,MATCH('Section 5. CAPEX'!I11,'Appendix B'!$B$5:$B$42,0)),0) -> 0 | L11: =IF(J11<=0,K11,J11) -> 0 | M11: 0 | N11: =M11*L11 -> 0
A12: 2 | K12: =IFERROR(INDEX('Appendix B'!$C$5:$C$42,MATCH('Section 5. CAPEX'!I12,'Appendix B'!$B$5:$B$42,0)),0) -> 0 | L12: =IF(J12<=0,K12,J12) -> 0 | M12: 0 | N12: =M12*L12 -> 0
A13: 3 | K13: =IFERROR(INDEX('Appendix B'!$C$5:$C$42,MATCH('Section 5. CAPEX'!I13,'Appendix B'!$B$5:$B$42,0)),0) -> 0 | L13: =IF(J13<=0,K13,J13) -> 0 | M13: 0 | N13: =M13*L13 -> 0
A14: 4 | K14: =IFERROR(INDEX('Appendix B'!$C$5:$C$42,MATCH('Section 5. CAPEX'!I14,'Appendix B'!$B$5:$B$42,0)),0) -> 0 | L14: =IF(J14<=0,K14,J14) -> 0 | M14: 0 | N14: =M14*L14 -> 0 | S14: Buildings
A15: 5 | K15: =IFERROR(INDEX('Appendix B'!$C$5:$C$42,MATCH('Section 5. CAPEX'!I15,'Appendix B'!$B$5:$B$42,0)),0) -> 0 | L15: =IF(J15<=0,K15,J15) -> 0 | M15: 0 | N15: =M15*L15 -> 0 | S15: Machines and equipment
A16: 6 | K16: =IFERROR(INDEX('Appendix B'!$C$5:$C$42,MATCH('Section 5. CAPEX'!I16,'Appendix B'!$B$5:$B$42,0)),0) -> 0 | L16: =IF(J16<=0,K16,J16) -> 0 | M16: 0 | N16: =M16*L16 -> 0 | S16: Vehicles
A17: 7 | K17: =IFERROR(INDEX('Appendix B'!$C$5:$C$42,MATCH('Section 5. CAPEX'!I17,'Appendix B'!$B$5:$B$42,0)),0) -> 0 | L17: =IF(J17<=0,K17,J17) -> 0 | M17: 0 | N17: =M17*L17 -> 0 | S17: Planes
A18: 8 | K18: =IFERROR(INDEX('Appendix B'!$C$5:$C$42,MATCH('Section 5. CAPEX'!I18,'Appendix B'!$B$5:$B$42,0)),0) -> 0 | L18: =IF(J18<=0,K18,J18) -> 0 | M18: 0 | N18: =M18*L18 -> 0 | S18: Computer hardware and software
A19: 9 | K19: =IFERROR(INDEX('Appendix B'!$C$5:$C$42,MATCH('Section 5. CAPEX'!I19,'Appendix B'!$B$5:$B$42,0)),0) -> 0 | L19: =IF(J19<=0,K19,J19) -> 0 | M19: 0 | N19: =M19*L19 -> 0 | S19: Furniture and fixtures
A20: 10 | K20: =IFERROR(INDEX('Appendix B'!$C$5:$C$42,MATCH('Section 5. CAPEX'!I20,'Appendix B'!$B$5:$B$42,0)),0) -> 0 | L20: =IF(J20<=0,K20,J20) -> 0 | M20: 0 | N20: =M20*L20 -> 0 | S20: Leasehold Improvements
A21: 11 | K21: =IFERROR(INDEX('Appendix B'!$C$5:$C$42,MATCH('Section 5. CAPEX'!I21,'Appendix B'!$B$5:$B$42,0)),0) -> 0 | L21: =IF(J21<=0,K21,J21) -> 0 | M21: 0 | N21: =M21*L21 -> 0 | S21: Intangible assets
A22: 12 | K22: =IFERROR(INDEX('Appendix B'!$C$5:$C$42,MATCH('Section 5. CAPEX'!I22,'Appendix B'!$B$5:$B$42,0)),0) -> 0 | L22: =IF(J22<=0,K22,J22) -> 0 | M22: 0 | N22: =M22*L22 -> 0 | S22: Capital work in progress
A23: 13 | K23: =IFERROR(INDEX('Appendix B'!$C$5:$C$42,MATCH('Section 5. CAPEX'!I23,'Appendix B'!$B$5:$B$42,0)),0) -> 0 | L23: =IF(J23<=0,K23,J23) -> 0 | M23: 0 | N23: =M23*L23 -> 0 | S23: Biological Assets
A24: 14 | K24: =IFERROR(INDEX('Appendix B'!$C$5:$C$42,MATCH('Section 5. CAPEX'!I24,'Appendix B'!$B$5:$B$42,0)),0) -> 0 | L24: =IF(J24<=0,K24,J24) -> 0 | M24: 0 | N24: =M24*L24 -> 0 | S24: Other
A25: 15 | K25: =IFERROR(INDEX('Appendix B'!$C$5:$C$42,MATCH('Section 5. CAPEX'!I25,'Appendix B'!$B$5:$B$42,0)),0) -> 0 | L25: =IF(J25<=0,K25,J25) -> 0 | M25: 0 | N25: =M25*L25 -> 0
A26: 16 | K26: =IFERROR(INDEX('Appendix B'!$C$5:$C$42,MATCH('Section 5. CAPEX'!I26,'Appendix B'!$B$5:$B$42,0)),0) -> 0 | L26: =IF(J26<=0,K26,J26) -> 0 | M26: 0 | N26: =M26*L26 -> 0
A27: 17 | K27: =IFERROR(INDEX('Appendix B'!$C$5:$C$42,MATCH('Section 5. CAPEX'!I27,'Appendix B'!$B$5:$B$42,0)),0) -> 0 | L27: =IF(J27<=0,K27,J27) -> 0 | M27: 0 | N27: =M27*L27 -> 0
A28: 18 | K28: =IFERROR(INDEX('Appendix B'!$C$5:$C$42,MATCH('Section 5. CAPEX'!I28,'Appendix B'!$B$5:$B$42,0)),0) -> 0 | L28: =IF(J28<=0,K28,J28) -> 0 | M28: 0 | N28: =M28*L28 -> 0
A29: 19 | K29: =IFERROR(INDEX('Appendix B'!$C$5:$C$42,MATCH('Section 5. CAPEX'!I29,'Appendix B'!$B$5:$B$42,0)),0) -> 0 | L29: =IF(J29<=0,K29,J29) -> 0 | M29: 0 | N29: =M29*L29 -> 0
A30: 20 | K30: =IFERROR(INDEX('Appendix B'!$C$5:$C$42,MATCH('Section 5. CAPEX'!I30,'Appendix B'!$B$5:$B$42,0)),0) -> 0 | L30: =IF(J30<=0,K30,J30) -> 0 | M30: 0 | N30: =M30*L30 -> 0
A31: 21 | K31: =IFERROR(INDEX('Appendix B'!$C$5:$C$42,MATCH('Section 5. CAPEX'!I31,'Appendix B'!$B$5:$B$42,0)),0) -> 0 | L31: =IF(J31<=0,K31,J31) -> 0 | M31: 0 | N31: =M31*L31 -> 0
A32: 22 | K32: =IFERROR(INDEX('Appendix B'!$C$5:$C$42,MATCH('Section 5. CAPEX'!I32,'Appendix B'!$B$5:$B$42,0)),0) -> 0 | L32: =IF(J32<=0,K32,J32) -> 0 | M32: 0 | N32: =M32*L32 -> 0
A33: 23 | K33: =IFERROR(INDEX('Appendix B'!$C$5:$C$42,MATCH('Section 5. CAPEX'!I33,'Appendix B'!$B$5:$B$42,0)),0) -> 0 | L33: =IF(J33<=0,K33,J33) -> 0 | M33: 0 | N33: =M33*L33 -> 0
A34: 24 | K34: =IFERROR(INDEX('Appendix B'!$C$5:$C$42,MATCH('Section 5. CAPEX'!I34,'Appendix B'!$B$5:$B$42,0)),0) -> 0 | L34: =IF(J34<=0,K34,J34) -> 0 | M34: 0 | N34: =M34*L34 -> 0
A35: 25 | K35: =IFERROR(INDEX('Appendix B'!$C$5:$C$42,MATCH('Section 5. CAPEX'!I35,'Appendix B'!$B$5:$B$42,0)),0) -> 0 | L35: =IF(J35<=0,K35,J35) -> 0 | M35: 0 | N35: =M35*L35 -> 0
A36: 26 | K36: =IFERROR(INDEX('Appendix B'!$C$5:$C$42,MATCH('Section 5. CAPEX'!I36,'Appendix B'!$B$5:$B$42,0)),0) -> 0 | L36: =IF(J36<=0,K36,J36) -> 0 | M36: 0 | N36: =M36*L36 -> 0
... A90: 80 | K90: =IFERROR(INDEX('Appendix B'!$C$5:$C$42,MATCH('Section 5. CAPEX'!I90,'Appendix B'!$B$5:$B$42,0)),0) -> 0 | L90: =IF(J90<=0,K90,J90) -> 0 | M90: 0 | N90: =M90*L90 -> 0
B91: Other Disallowable Costs (unallocated cost)8 | L91: 0 | M91: 0 | N91: =M91*L91 -> 0 | O91: =IF(M91>(30%*C5),"Need LCGPA approval","")
B92: Unbilled Accrued Expenses9 | L92: 0 | M92: 0 | N92: =M92*L92 -> 0
B93: Remaining Capital Expenditures | L93: =IFERROR(SUMPRODUCT($M$11:$M$91,$L$11:$L$91)/SUM($M$11:$M$91),0) -> 0 | M93: =C5-SUM(M11:M92) -> 0 | N93: =M93*L93 -> 0
B94: Total Capital Expenditures | M94: =SUM(M11:M93) -> 0 | N94: =SUM(N9:N93) -> 0
B95: Has the number of suppliers been covered? | M95: =IFERROR(IF(SUM(M11:M91)=0,"",IF(OR(COUNTIFS($M$11:$M$90,">"&0)=80,M93=0),"Yes","No")),"No")
B97: 1. Does not include the value of assets transferred from other parties, materials to be resold (inventory) and lands.
...

Sheet Section 6. Capacity Building
B1: Section 6: Capacity Building
B2: Contract Information
B3: Entity Name | C3: =IF('Section 1. General Information'!$C$9:$D$9="","",'Section 1. General Information'!$C$9:$D$9)
B4: Tender Name | C4: =IF('Section 1. General Information'!$C$4:$D$4="","",'Section 1. General Information'!$C$4:$D$4)
B5: Contract Start Date (DD/MM/YYYY) | C5: =IF('Section 1. General Information'!$C$5:$D$5="","",'Section 1. General Information'!$C$5:$D$5)
B6: Contract End Date (DD/MM/YYYY) | C6: =IF('Section 1. General Information'!$C$6:$D$6="","",'Section 1. General Information'!$C$6:$D$6)
B8: 6.1 Expenses on Training of Saudis
B9: Expenses for the reported financial year (SAR)1 | C9: 0
B11: 6.2 Expenses on KSA Suppliers Development
B12: Expenses for the reported financial year (SAR)2 | C12: 0
B14: 6.3 Expenses on KSA Research and Development
B15: Expenses for the reported financial year (SAR)3 | C15: 0
B16: Total Revenue (SAR) | C16: 0
B17: Research and Development Incentive Score (%) | C17: =IFERROR(IF((C15/C16)>=2%,10%,10%*((C15/C16)/2%)),0) -> 0
B19: 1. Expenses on the training of Saudi employees for the reported financial year, this includes the cost of trainees and scholarships. Note that the expenses of this section shall not be repeated with other key performance indicators.
B20: 2. Expenses on the development of suppliers (who have a Saudi commercial registration number or license number in KSA) for the reported financial year, through training and contribution to enhance suppliers' capabilities. Note that the expenses of this section shall not be repeated with other key performance indicators.
B21: 3. Operating expenses for R&D activities in the Kingdom of Saudi Arabia for the reported financial year. An incentive score of up to 10% is calculated when the spent on research and development is 2% of the total revenue of the entity.

Sheet Section 7. Depreciation & Amor.
B1: Section 7: Depreciation and Amortization
B2: Contract Information
B3: Entity Name | C3: =IF('Section 1. General Information'!$C$9:$D$9="","",'Section 1. General Information'!$C$9:$D$9)
B4: Tender Name | C4: =IF('Section 1. General Information'!$C$4:$D$4="","",'Section 1. General Information'!$C$4:$D$4)
B5: Contract Start Date (DD/MM/YYYY) | C5: =IF('Section 1. General Information'!$C$5:$D$5="","",'Section 1. General Information'!$C$5:$D$5)
B6: Contract End Date (DD/MM/YYYY) | C6: =IF('Section 1. General Information'!$C$6:$D$6="","",'Section 1. General Information'!$C$6:$D$6)
B8: 7.1 Depreciation and Amortization of Assets in the Kingdom of Saudi Arabia
B9: Total depreciation and amortization (SAR) | C9: 0
B10: Contribution to Local Content (SAR) | C10: =F29 -> 0
B11: Local Content Score (%) | C11: =IFERROR(C10/C9,0) -> 0
B13: 7.2 Depreciation and Amortization by Asset class in the Kingdom of Saudi Arabia
B14: Asset Class | C14: Examples of Assets in Productive Asset class | D14: Local Assets | E14: Foreign Assets | F14: Local Content contribution (SAR)1
D15: Depreciation / Amortization (SAR) | E15: Depreciation / Amortization (SAR)
A16: 1 | B16: Building and Land Improvements2 | C16: Buildings / Land and Building Improvements | D16: 0 | F16: =D16*100% -> 0
A17: =A16+1 -> 2 | B17: Furniture and Fixtures | C17: Office furniture, desks, cubicles, office chairs | D17: 0 | E17: 0 | F17: =(D17*100%)+(E17*30%) -> 0 | G17: =IF(D17>1%*'Section 2. Evaluation'!$C$17,"Need to be tested","")
A18: =A17+1 -> 3 | B18: Machinery and Equipment | C18: Industrial equipment, testing equipment, information and communication technology equipment | D18: 0 | E18: 0 | F18: =(D18*100%)+(E18*30%) -> 0 | G18: =IF(D18>1%*'Section 2. Evaluation'!$C$17,"Need to be tested","")
A19: =A18+1 -> 4 | B19: Vehicles | C19: Mobile cranes, Trucks, vans, cars, trailers, fork lifts | D19: 0 | E19: 0 | F19: =(D19*100%)+(E19*30%) -> 0 | G19: =IF(D19>1%*'Section 2. Evaluation'!$C$17,"Need to be tested","")
A20: =A19+1 -> 5 | B20: Infrastructure | C20: Infrastructure works such as road networks, energy, and water | D20: 0 | E20: 0 | F20: =(D20*100%)+(E20*30%) -> 0 | G20: =IF(D20>1%*'Section 2. Evaluation'!$C$17,"Need to be tested","")
A21: =A20+1 -> 6 | B21: Investment properties | C21: Real estate assets such as residential buildings and commercial buildings | D21: 0 | E21: 0 | F21: =(D21*100%)+(E21*30%) -> 0 | G21: =IF(D21>1%*'Section 2. Evaluation'!$C$17,"Need to be tested","")
A22: =A21+1 -> 7 | B22: Right-of-Use for leases, machinery, equipment, and vehicles | C22: Lease agreements for buildings, equipment, and vehicles | D22: 0 | E22: 0 | F22: =(D22*100%)+(E22*30%) -> 0 | G22: =IF(D22>1%*'Section 2. Evaluation'!$C$17,"Need to be tested","")
A23: =A22+1 -> 8 | B23: Right-of-Use for Systems and Applications | C23: License to use computer software, systems | D23: 0 | E23: 0 | F23: =(D23*100%)+(E23*30%) -> 0 | G23: =IF(D23>1%*'Section 2. Evaluation'!$C$17,"Need to be tested","")
A24: =A23+1 -> 9 | B24: Other (Please describe) | C24: Other (please give examples) | D24: 0 | E24: 0 | F24: =(D24*100%)+(E24*30%) -> 0 | G24: =IF(D24>1%*'Section 2. Evaluation'!$C$17,"Need to be tested","")
A25: =A24+1 -> 10 | B25: Other (Please describe) | C25: Other (please give examples) | D25: 0 | E25: 0 | F25: =(D25*100%)+(E25*30%) -> 0 | G25: =IF(D25>1%*'Section 2. Evaluation'!$C$17,"Need to be tested","")
A26: =A25+1 -> 11 | B26: Other (Please describe) | C26: Other (please give examples) | D26: 0 | E26: 0 | F26: =(D26*100%)+(E26*30%) -> 0 | G26: =IF(D26>1%*'Section 2. Evaluation'!$C$17,"Need to be tested","")
A27: =A26+1 -> 12 | B27: Other (Please describe) | C27: Other (please give examples) | D27: 0 | E27: 0 | F27: =(D27*100%)+(E27*30%) -> 0 | G27: =IF(D27>1%*'Section 2. Evaluation'!$C$17,"Need to be tested","")
A28: =A27+1 -> 13 | B28: Other (Please describe) | C28: Other (please give examples) | D28: 0 | E28: 0 | F28: =(D28*100%)+(E28*30%) -> 0 | G28: =IF(D28>1%*'Section 2. Evaluation'!$C$17,"Need to be tested","")
B29: Total depreciation and amortization | D29: =SUM(D16:D28) -> 0 | E29: =SUM(E17:E28) -> 0 | F29: =SUM(F16:F28) -> 0
B31: 1. 100% Local Content Score for assets manufactured in the KSA, and 30% for assets manufactured outside KSA.
B32: 2. All depreciataion related to this category is considered 100% local content as long as they are located in KSA.

Sheet Appendix A
B1: Appendix A: Reconciliation, Revenue, and Dividends
B2: A.1 Income Statement Line Items
B3: Cost of Revenue / Direct cost | F3: 0
B4: General and Administrative Expenses | F4: 0
B5: Selling and Distribution Expenses | F5: 0
B6: Finance costs | F6: 0
B7: Zakat and income taxes | F7: 0
B8: Other expenses | F8: 0
B9: Total cost per audited financial statements | F9: =SUM(F3:F8) -> 0
B11: A.2 Less Eliminations
B12: Section 3. Labor | F12: ='Section 3. Labor'!E10 -> 0
B13: Section 6. Capacity Building | F13: ='Section 6. Capacity Building'!C9+'Section 6. Capacity Building'!C12+'Section 6. Capacity Building'!C15 -> 0
B14: Section 7. Depreciation and Amortization | F14: ='Section 7. Depreciation & Amor.'!D29+'Section 7. Depreciation & Amor.'!E29 -> 0
B15: Zakat and income taxes | F15: =F7 -> 0
B16: Customs and duties | F16: 0
B17: Provisions (Exc.,End of service provisons) | F17: 0
B18: Government fees (e.g., visa fees) | F18: 0
B19: Losses (e.g., foreign currency exchange and any other losses) | F19: 0
B20: Other (please describe) | F20: 0
B21: Other (please describe) | F21: 0
B22: Other (please describe) | F22: 0
B23: Other (please describe) | F23: 0
B24: Other (please describe) | F24: 0
B25: Other (please describe) | F25: 0
B26: Total eliminations | F26: =SUM(F12:F25) -> 0
B27: Section 4. Goods and Services | F27: =F9-F26 -> 0 | G27: =IF(F27='Section 4. Goods and Services'!F9, "","Not match Section 4")
B29: A.3 Revenue and Dividends
B30: 3.1 Revenue for 10 customers of the entity (Mandatory for factories, optional for non-factory entities)
B31: Customer's Name | D31: Unified National Number or KSA Commercial registration number | E31: Brief description of the goods or services provided | F31: Total Revenue (SAR)
A32: 1 | F32: 0
A33: 2 | F33: 0
A34: 3 | F34: 0
A35: 4 | F35: 0
A36: 5 | F36: 0
A37: 6 | F37: 0
A38: 7 | F38: 0
A39: 8 | F39: 0
A40: 9 | F40: 0
A41: 10 | F41: 0
B42: 3.2 Total Revenue and Net Profit (Loss)
...

Sheet Appendix B
B1: Appendix B
B2: B.1 List of Sector Local Content Scores
B3: General information on Sector Local Content Scores
B4: Sector | C4: Local Content Score (%) | D4: Description | E4: ISIC Code
B5: 1_SERVICES - KSA Accommodation and Facility Rental | C5: 0.6 | D5: The procurement of Services for short-term accommodation (e.g. Hotels) Camping grounds, Other accommodation (e.g. student residences) and rental of office buildings, compounds, warehouses, etc. | E5: 55, 68102
B6: 2_SERVICES - KSA Food and Beverages | C6: 0.4 | D6: The procurement of Services for food and beverages (e.g. Restaurants, catering; the purchase of ready-made food & beverage products is not included) | E6: 56
B7: 3_SERVICES - KSA Industrial Services | C7: 0.36 | D7: The procurement of testing, inspection, certification, calibration, maintenance, blasting, painting, coating and galvanizing services, steam and air conditioning supply | E7: 25921, 33, 35, Exc. 351&352, 38 Exc.381103&383, 712
B8: 4_SERVICES - KSA Security Services | C8: 0.82 | D8: The procurement of security services including guard and patrol services (e.g. Security of facilities) and armored car services, operation of electronic security alarm systems (e.g. fire alarm) | E8: 80, 811001
B9: 5_SERVICES - KSA local Professional Services | C9: 0.5 | D9: The procurement of Professional consulting, Such as engineering, accounting, legal, management consultancy (e.g. strategic, financial planning, budgeting, marketing, policies, HR) | E9: 69-74 Exc. 712
B10: 6_SERVICES - KSA local representative of Foreign professional service provider | C10: 0.2 | D10: The procurement of Professional consulting, Such as engineering, accounting, legal, management consultancy (e.g. strategic, financial planning, budgeting, marketing, policies, HR) provided by a local representative of foreign professional service provider | E10: 69-74 Exc. 712
B11: 7_SERVICES - KSA Real Estate | C11: 0.48 | D11: The procurement of services for selling or buying real estate, providing other real estate services such as appraising real estate or acting as real estate escrow agents. Exc. Facility rental | E11: 68 Exc.68102
B12: 8_SERVICES - KSA Construction | C12: 0.4 | D12: The procurement of construction Services, specialized construction activities for buildings and civil engineering works (e.g., contracting; the procurement of pure construction materials is categorized under Goods sectors), interior and exterior painting of buildings | E12: 41-43
B13: 9_SERVICES - KSA Education | C13: 0.66 | D13: The procurement of all education activities for any profession, oral or written as well as by radio and television or other means of communication (e.g., professional training, language education) | E13: 75, 85
B14: 10_SERVICES - KSA Finance and Insurance | C14: 0.75 | D14: The procurement of all financial Services (e.g., banking, funds management); this category also includes the procurement of insurance and pension Services (e.g., health insurance, transport insurance, accident and fire insurance) | E14: 64-66
B15: 11_SERVICES - KSA Healthcare | C15: 0.38 | D15: The procurement of all Services related to healthcare (the procurement of healthcare equipment and pharmaceuticals is categorized under Goods sectors) | E15: 86-88
B16: 12_SERVICES - KSA Public Administration and Defence | C16: 0.69 | D16: The procurement of Services produced by government bodies (General public administration activities, Foreign affairs, Defence activities, etc) | E16: 84
B17: 13_SERVICES - KSA Transport and Logistics | C17: 0.45 | D17: The procurement of transport and logistics services from locally based service providers. This sector includes shipping, transportation, cargo services and Saudi based airlines (including freight forward),(Foreign airlines booked by local agency is categorized under foreign service agent),Exc. Rental of cars | E17: 49-53 Exc.49225, 79-7911
B18: 14_SERVICES - KSA Onshore Drilling | C18: 0.3 | D18: The procurement of onshore drilling services | E18: 06, 091
... B30: 26_GOODS - KSA Chemicals & Oil and Gas | C30: 0.61 | D30: The procurement of locally produced chemicals, plastics, manufactured chemical Goods, and Oil & Gas product (e.g. Rubber). | E30: 19-20, 22, 352
B31: 27_GOODS - KSA Chemical Blending | C31: 0.29 | D31: The procurement of locally produced chemicals where the raw material is imported. This sector includes paint manufacturers | E31: 20
B32: 28_GOODS - KSA Machinery and Equipment | C32: 0.25 | D32: The procurement of locally produced machinery and equipment | E32: 265-268, 28 Exc.2813&2814, 29-30
B33: 29_GOODS - KSA Electrical Materials | C33: 0.4 | D33: The procurement of locally produced electrical materials including switch gears, junction boxes, trays, conduits, fixtures, inverters skid and other electrical materials, , Excluding PV panels and electrical inverters. | E33: 27, 2814
B34: 30_GOODS - KSA Mining | C34: 0.45 | D34: The procurement of locally produced raw materials extracted by the mining industry (e.g., coal, metal ores) | E34: 05, 07-08
B35: 31_GOODS - KSA Static Equipment | C35: 0.3 | D35: The procurement of locally produced static equipment such as tanks, pressure vessels and valves (control valves excluded) and steel manufacturers and structural | E35: 24-25 Exc.25114&25921, 2813
B36: 32_GOODS - KSA Cement and Gypsum | C36: 0.5 | D36: The procurement of locally produced cement, concrete and gypsum | E36: 2394-2395
B37: 33_GOODS - KSA Steel Rebar Manufacturing | C37: 0.6 | D37: The procurement of locally produced steel rebar | E37: 25114
B38: 34_GOODS - KSA IT & Telecom Manufacturing | C38: 0.15 | D38: The procurement of manufacturing of computer& electronic components, communication equipment (agents/resellers are not considered) | E38: 261-264
B39: 35_GOODS - KSA Other Manufacturing | C39: 0.3 | D39: The procurement of locally produced paper products, wood products, furniture, secondary raw material, textiles, pharmaceuticals and other industries, Including PV panels and electrical inverters. | E39: 13-18, 21, 23 Exc.2394&2395, 31-32 (Inc. 2790 PV panels and Electrical inverters)
B40: 36_GOODS - KSA Recyclers | C40: 0.7 | D40: The procurement of locally recycled metal scrap, paper, plastic and rubber | E40: 381103, 383
B41: 37_GOODS - KSA Agent or Distributor | C41: 0.05 | D41: The procurement of any kind of Goods from KSA Suppliers who do not produce these Goods; instead, distributors/ traders import and distribute these Goods | E41: 45-47
B42: 38_GOODS - Foreign | C42: 0 | D42: The procurement of Goods from foreign producers, i.e. entities without legal registration in KSA (direct Goods imports) | E42: N /A (supplier type)
